<?xml version="1.0"?>

<robot name="diffbot" xmlns:xacro="http://www.ros.org/wiki/xacro">

    <!-- Materials -->
    <material name="blue">
        <color rgba="0 0 0.8 1"/>
    </material>

    <material name="black">
        <color rgba="0 0 0 1"/>
    </material>

    <material name="white">
        <color rgba="1 1 1 1"/>
    </material>

    <material name="red">
        <color rgba="1 0 0 1"/>
    </material>

    <material name="green">
        <color rgba="0 1 0 1"/>
    </material>

    <!-- Base Link -->
    <link name="base_link">
        <visual>
            <geometry>
                <box size="0.5 0.3 0.15"/>
            </geometry>
            <material name="blue"/>
        </visual>
        <collision>
            <geometry>
                <box size="0.5 0.3 0.15"/>
            </geometry>
        </collision>
        <!-- <inertial>
            <mass value="5.0"/>
            <inertia ixx="0.1" ixy="0" ixz="0" iyy="0.1" iyz="0" izz="0.1"/>
        </inertial> -->
    </link>

    <!-- Left Wheel -->
    <link name="left_wheel">
        <visual>
            <geometry>
                <cylinder length="0.05" radius="0.1"/>
            </geometry>
            <material name="black"/>
        </visual>
        <collision>
            <geometry>
                <cylinder length="0.05" radius="0.1"/>
            </geometry>
        </collision>
        <inertial>
            <mass value="0.5"/>
            <inertia ixx="0.01" ixy="0" ixz="0" iyy="0.01" iyz="0" izz="0.01"/>
        </inertial>
    </link>

    <!-- Right Wheel -->
    <link name="right_wheel">
        <visual>
            <geometry>
                <cylinder length="0.05" radius="0.1"/>
            </geometry>
            <material name="black"/>
        </visual>
        <collision>
            <geometry>
                <cylinder length="0.05" radius="0.1"/>
            </geometry>
        </collision>
        <inertial>
            <mass value="0.5"/>
            <inertia ixx="0.01" ixy="0" ixz="0" iyy="0.01" iyz="0" izz="0.01"/>
        </inertial>
    </link>

    <!-- Caster Wheel -->
    <link name="caster_wheel">
        <visual>
            <geometry>
                <sphere radius="0.05"/>
            </geometry>
            <material name="black"/>
        </visual>
        <collision>
            <geometry>
                <sphere radius="0.05"/>
            </geometry>
        </collision>
        <inertial>
            <mass value="0.1"/>
            <inertia ixx="0.01" ixy="0" ixz="0" iyy="0.01" iyz="0" izz="0.01"/>
        </inertial>
    </link>

    <!-- Camera -->
    <link name="camera">
        <visual>
            <geometry>
                <box size="0.05 0.05 0.05"/>
            </geometry>
            <material name="red"/>
        </visual>
        <collision>
            <geometry>
                <box size="0.05 0.05 0.05"/>
            </geometry>
        </collision>
        <inertial>
            <mass value="0.1"/>
            <inertia ixx="0.001" ixy="0" ixz="0" iyy="0.001" iyz="0" izz="0.001"/>
        </inertial>
    </link>

    <!-- Lidar -->
    <link name="lidar">
        <visual>
            <geometry>
                <cylinder length="0.05" radius="0.1"/>
            </geometry>
            <material name="green"/>
        </visual>
        <collision>
            <geometry>
                <cylinder length="0.05" radius="0.1"/>
            </geometry>
        </collision>
        <inertial>
            <mass value="0.2"/>
            <inertia ixx="0.001" ixy="0" ixz="0" iyy="0.001" iyz="0" izz="0.001"/>
        </inertial>
    </link>

    <!-- Left Wheel Joint -->
    <joint name="left_wheel_joint" type="continuous">
        <parent link="base_link"/>
        <child link="left_wheel"/>
        <origin xyz="-0.2 0.175 -0.05" rpy="-1.5708 0 0"/>
        <axis xyz="0 0 1"/>
    </joint>

    <!-- Right Wheel Joint -->
    <joint name="right_wheel_joint" type="continuous">
        <parent link="base_link"/>
        <child link="right_wheel"/>
        <origin xyz="-0.2 -0.175 -0.05" rpy="-1.5708 0 0"/>
        <axis xyz="0 0 1"/>
    </joint>

    <!-- Caster Wheel Joint -->
    <joint name="caster_wheel_joint" type="fixed">
        <parent link="base_link"/>
        <child link="caster_wheel"/>
        <origin xyz="0.2 0 -0.1"/>
        <axis xyz="0 0 1"/>
    </joint>

    <!-- Camera Joint -->
    <joint name="camera_joint" type="fixed">
        <parent link="base_link"/>
        <child link="camera"/>
        <origin xyz="0.27 0 0.01" rpy="0 0 0"/>
        <axis xyz="0 0 1"/>
    </joint>

    <!-- Lidar Joint -->
    <joint name="lidar_joint" type="fixed">
        <parent link="base_link"/>
        <child link="lidar"/>
        <origin xyz="0 0 0.1" rpy="0 0 0"/>
        <axis xyz="0 0 1"/>
    </joint>

    <!-- Gazebo Colors -->
    <gazebo reference="base_link">
        <material>Gazebo/Blue</material>
    </gazebo>

    <gazebo reference="left_wheel">
        <material>Gazebo/Black</material>
        <mu1 value="1.0"/>
        <mu2 value="1.0"/>
    </gazebo>

    <gazebo reference="right_wheel">
        <material>Gazebo/Black</material>
        <mu1 value="1.0"/>
        <mu2 value="1.0"/>
    </gazebo>

    <gazebo reference="caster_wheel">
        <material>Gazebo/Black</material>
        <mu1 value="0.1"/>
        <mu2 value="0.1"/>
    </gazebo>

    <gazebo reference="camera">
        <material>Gazebo/Red</material>
    </gazebo>

    <gazebo reference="lidar">
        <material>Gazebo/Green</material>
    </gazebo>

    <!-- Gazebo plugin for differential drive -->
    <gazebo>
        <plugin filename="gz-sim-diff-drive-system" name="gz::sim::systems::DiffDrive">
            <odom_publisher_frequency>50</odom_publisher_frequency>
            <left_joint>left_wheel_joint</left_joint>
            <right_joint>right_wheel_joint</right_joint>
            <wheel_separation>0.35</wheel_separation>
            <wheel_diameter>0.2</wheel_diameter>
            <max_wheel_torque>20</max_wheel_torque>
            <max_linear_acceleration>1.0</max_linear_acceleration>
            <topic>cmd_vel</topic>
            <publish_odom>true</publish_odom>
            <publish_odom_tf>true</publish_odom_tf>
            <publish_wheel_tf>true</publish_wheel_tf>
            <odom_topic>odom</odom_topic>
            <frame_id>odom</frame_id>
            <child_frame_id>base_link</child_frame_id>
        </plugin>
	
        <plugin filename="gz-sim-joint-state-publisher-system" name="gz::sim::systems::JointStatePublisher">
            <update_rate>50</update_rate>
            <joint_name>left_wheel_joint</joint_name>
            <joint_name>right_wheel_joint</joint_name>
        </plugin>
  </gazebo>

<!-- Camera Plugin -->
<gazebo reference="camera">
    <sensor type="camera" name="camera">
        <update_rate>30.0</update_rate>
        <camera name="head">
            <camera_info_topic>camera/camera_info</camera_info_topic>
            <horizontal_fov>1.3962634</horizontal_fov>
            <image>
                <width>800</width>
                <height>600</height>
                <format>R8G8B8</format>
            </image>
            <clip>
                <near>0.02</near>
                <far>300</far>
            </clip>
            <noise>
                <type>gaussian</type>
                <mean>0.0</mean>
                <stddev>0.007</stddev>
            </noise>
        </camera>
        <topic>camera/image_raw</topic>
        <gz_frame_id>camera</gz_frame_id>
    </sensor>
</gazebo>
<!-- Lidar Plugin -->
<gazebo reference="lidar">
    <sensor type="gpu_lidar" name="lidar">
        <pose>0 0 0 0 0 0</pose>
        <always_on>true</always_on>
        <visualize>true</visualize>
        <update_rate>10</update_rate>
        <lidar>
            <scan>
                <horizontal>
                    <samples>360</samples>
                    <resolution>1</resolution>
                    <min_angle>-3.14159</min_angle>
                    <max_angle>3.14159</max_angle>
                </horizontal>
            </scan>
            <range>
                <min>0.2</min>
                <max>30.0</max>
                <resolution>0.01</resolution>
            </range>
            <noise>
                <type>gaussian</type>
                <mean>0.0</mean>
                <stddev>0.01</stddev>
            </noise>
        </lidar>
        <topic>scan</topic>
        <gz_frame_id>lidar</gz_frame_id>
    </sensor>
</gazebo>


</robot>
