<?xml version="1.0"?>
<robot xmlns:xacro="http://www.ros.org/wiki/xacro" name="simple_arm">

    <!-- Materials -->
    <material name="blue">
        <color rgba="0 0 0.8 1"/>
    </material>
    <material name="red">
        <color rgba="0.8 0 0 1"/>
    </material>

    <!-- Base Link -->
    <link name="base_link">
        <visual>
            <geometry>
                <cylinder radius="0.1" length="0.05"/>
            </geometry>
            <material name="blue"/>
        </visual>
        <collision>
            <geometry>
                <cylinder radius="0.1" length="0.05"/>
            </geometry>
        </collision>
        <inertial>
            <mass value="1.0"/>
            <inertia ixx="0.0027" ixy="0.0" ixz="0.0" iyy="0.0027" iyz="0.0" izz="0.005"/>
        </inertial>
    </link>

    <!-- Link 1 -->
    <link name="link1">
        <visual>
            <geometry>
                <box size="0.5 0.1 0.1"/>
            </geometry>
            <origin xyz="0.25 0 0" rpy="0 0 0"/>
            <material name="red"/>
        </visual>
        <collision>
            <geometry>
                <box size="0.5 0.1 0.1"/>
            </geometry>
            <origin xyz="0.25 0 0" rpy="0 0 0"/>
        </collision>
        <inertial>
            <mass value="1.0"/>
            <inertia ixx="0.004" ixy="0.0" ixz="0.0" iyy="0.021" iyz="0.0" izz="0.021"/>
        </inertial>
    </link>

    <!-- Link 2 -->
    <link name="link2">
        <visual>
            <geometry>
                <box size="0.5 0.1 0.1"/>
            </geometry>
            <origin xyz="0.25 0 0" rpy="0 0 0"/>
            <material name="blue"/>
        </visual>
        <collision>
            <geometry>
                <box size="0.5 0.1 0.1"/>
            </geometry>
            <origin xyz="0.25 0 0" rpy="0 0 0"/>
        </collision>
        <inertial>
            <mass value="1.0"/>
            <inertia ixx="0.004" ixy="0.0" ixz="0.0" iyy="0.021" iyz="0.0" izz="0.021"/>
        </inertial>
    </link>

    <!-- Joints -->
    <joint name="base_link1_joint" type="revolute">
        <parent link="base_link"/>
        <child link="link1"/>
        <origin xyz="0 0 0.025" rpy="0 0 0"/>
        <axis xyz="0 0 1"/>
        <limit lower="-3.14" upper="3.14" effort="100" velocity="1"/>
    </joint>

    <joint name="link1_link2_joint" type="revolute">
        <parent link="link1"/>
        <child link="link2"/>
        <origin xyz="0.5 0 0" rpy="0 0 0"/>
        <axis xyz="0 1 0"/>
        <limit lower="-3.14" upper="3.14" effort="100" velocity="1"/>
    </joint>

    <!-- Gazebo plugin for joint state publisher -->
    <!-- <gazebo>
        <plugin name="gazebo_ros_joint_state_publisher"
                filename="libgazebo_ros_joint_state_publisher.so">
            <update_rate>20</update_rate>
            <joint_name>base_link1_joint</joint_name>
            <joint_name>link1_link2_joint</joint_name>
        </plugin>
    </gazebo> -->

    <!-- ros2_control plugin -->
    <gazebo>
        <plugin name="gazebo_ros2_control" filename="libgazebo_ros2_control.so">
            <parameters>$(find simple_arm_description)/config/simple_arm_controllers.yaml</parameters>
        </plugin>
    </gazebo>

    <!-- ros2_control tags -->
    <ros2_control name="GazeboSystem" type="system">
        <hardware>
            <plugin>gazebo_ros2_control/GazeboSystem</plugin>
        </hardware>
        
        <joint name="base_link1_joint">
            <command_interface name="position">
                <param name="min">-3.14</param>
                <param name="max">3.14</param>
            </command_interface>
            <state_interface name="position"/>
            <state_interface name="velocity"/>
            <state_interface name="effort"/>
        </joint>

        <joint name="link1_link2_joint">
            <command_interface name="position">
                <param name="min">-3.14</param>
                <param name="max">3.14</param>
            </command_interface>
            <state_interface name="position"/>
            <state_interface name="velocity"/>
            <state_interface name="effort"/>
        </joint>
    </ros2_control>

    <!-- Gazebo materials -->
    <gazebo reference="base_link">
        <material>Gazebo/Blue</material>
    </gazebo>

    <gazebo reference="link1">
        <material>Gazebo/Red</material>
    </gazebo>

    <gazebo reference="link2">
        <material>Gazebo/Blue</material>
    </gazebo>

</robot>