<?xml version="1.0"?>
<robot name="my_robot" xmlns:xacro="http://ros.org/wiki/xacro">

    <material name="grey">
        <color rgba="0.7 0.7 0.7 1" />
    </material>
    <material name="green">
        <color rgba="0 0.6 0 1" />
    </material>
    <material name="white">
        <color rgba="1 1 1 1" />
    </material>

    <link name="base_footprint" />

    <link name="base_link">
        <visual>
            <geometry>
                <box size="0.6 0.4 0.2" />
            </geometry>
            <origin xyz="0 0 0.1" rpy="0 0 0" />
            <material name="green" />
        </visual>
        <collision>
            <geometry>
                <box size="0.6 0.4 0.2" />
            </geometry>
            <origin xyz="0 0 0.1" rpy="0 0 0" />
        </collision>
        <inertial>
            <origin xyz="0 0 0.1" rpy="0 0 0" />
            <mass value="1.0" />
            <inertia ixx="0.1" ixy="0" ixz="0" iyy="0.1" iyz="0" izz="0.1" />
        </inertial>
    </link>

    <link name="lidar">
        <visual>
            <geometry>
                <cylinder radius="0.1" length="0.05" />
            </geometry>
            <origin xyz="0 0 0" rpy="0 0 0" />
            <material name="white" />
        </visual>
        <collision>
            <geometry>
                <cylinder radius="0.1" length="0.05" />
            </geometry>
            <origin xyz="0 0 0" rpy="0 0 0" />
        </collision>
        <inertial>
            <origin xyz="0 0 0" rpy="0 0 0" />
            <mass value="0.01" />
            <inertia ixx="0.0001" ixy="0" ixz="0" iyy="0.0001" iyz="0" izz="0.0001" />
        </inertial>
    </link>

    <link name="left_back_wheel">
        <visual>
            <geometry>
                <cylinder radius="0.1" length="0.05" />
            </geometry>
            <origin xyz="0 0 0" rpy="1.57 0 0" />
            <material name="white" />
        </visual>
        <collision>
            <geometry>
                <cylinder radius="0.1" length="0.05" />
            </geometry>
            <origin xyz="0 0 0" rpy="1.57 0 0" />
        </collision>
        <inertial>
            <origin xyz="0 0 0" rpy="1.57 0 0" />
            <mass value="0.5" />
            <inertia ixx="0.05" ixy="0" ixz="0" iyy="0.05" iyz="0" izz="0.05" />
        </inertial>
    </link>

    <link name="right_back_wheel">
        <visual>
            <geometry>
                <cylinder radius="0.1" length="0.05" />
            </geometry>
            <origin xyz="0 0 0" rpy="1.57 0 0" />
            <material name="white" />
        </visual>
        <collision>
            <geometry>
                <cylinder radius="0.1" length="0.05" />
            </geometry>
            <origin xyz="0 0 0" rpy="1.57 0 0" />
        </collision>
        <inertial>
            <origin xyz="0 0 0" rpy="1.57 0 0" />
            <mass value="0.5" />
            <inertia ixx="0.05" ixy="0" ixz="0" iyy="0.05" iyz="0" izz="0.05" />
        </inertial>
    </link>
    
    <link name="left_front_wheel">
        <visual>
            <geometry>
                <cylinder radius="0.1" length="0.05" />
            </geometry>
            <origin xyz="0 0 0" rpy="1.57 0 0" />
            <material name="white" />
        </visual>
        <collision>
            <geometry>
                <cylinder radius="0.1" length="0.05" />
            </geometry>
            <origin xyz="0 0 0" rpy="1.57 0 0" />
        </collision>
        <inertial>
            <origin xyz="0 0 0" rpy="1.57 0 0" />
            <mass value="0.5" />
            <inertia ixx="0.05" ixy="0" ixz="0" iyy="0.05" iyz="0" izz="0.05" />
        </inertial>
    </link>

    <link name="right_front_wheel">
        <visual>
            <geometry>
                <cylinder radius="0.1" length="0.05" />
            </geometry>
            <origin xyz="0 0 0" rpy="1.57 0 0" />
            <material name="white" />
        </visual>
        <collision>
            <geometry>
                <cylinder radius="0.1" length="0.05" />
            </geometry>
            <origin xyz="0 0 0" rpy="1.57 0 0" />
        </collision>
        <inertial>
            <origin xyz="0 0 0" rpy="1.57 0 0" />
            <mass value="0.5" />
            <inertia ixx="0.05" ixy="0" ixz="0" iyy="0.05" iyz="0" izz="0.05" />
        </inertial>
    </link>

    <joint name="base_joint" type="fixed">
        <parent link="base_footprint" />
        <child link="base_link" />
        <origin xyz="0 0 0.1" rpy="0 0 0" />
    </joint>

    <joint name="base_lidar_joint" type="fixed">
        <parent link="base_link" />
        <child link="lidar" />
        <origin xyz="0 0 0.225" rpy="0 0 0" />
    </joint>

    <joint name="base_left_wheel_joint" type="continuous">
        <parent link="base_link" />
        <child link="left_back_wheel" />
        <origin xyz="-0.15 0.225 0" rpy="0 0 0" />
        <axis xyz="0 1 0" />
    </joint>

    <joint name="base_left_front_joint" type="continuous">
        <parent link="base_link" />
        <child link="left_front_wheel" />
        <origin xyz="0.15 0.225 0" rpy="0 0 0" />
        <axis xyz="0 1 0" />
    </joint>

    <joint name="base_right_front_joint" type="continuous">
        <parent link="base_link" />
        <child link="right_front_wheel" />
        <origin xyz="0.15 -0.225 0" rpy="0 0 0" />
        <axis xyz="0 1 0" />
    </joint>

    <joint name="base_right_back_joint" type="continuous">
        <parent link="base_link" />
        <child link="right_back_wheel" />
        <origin xyz="-0.15 -0.225 0" rpy="0 0 0" />
        <axis xyz="0 1 0" />
    </joint>


    <!-- Gazebo specific properties for base_link -->
    <gazebo reference="base_link">
        <material>Gazebo/Green</material> <!-- Adjust material as needed -->
        <mu1>100</mu1>
        <mu2>100</mu2>
        <kp>1000000.0</kp>
        <kd>1000.0</kd>
        <static>false</static>
    </gazebo>

    <!-- Gazebo specific properties for lidar -->
    <gazebo reference="lidar">
        <material>Gazebo/White</material> <!-- Adjust material as needed -->
        <mu1>100</mu1>
        <mu2>100</mu2>
        <kp>1000000.0</kp>
        <kd>1000.0</kd>
        <static>false</static>
    </gazebo>

    <!-- Gazebo specific properties for left_back_wheel -->
    <gazebo reference="left_back_wheel">
        <material>Gazebo/White</material> <!-- Adjust material as needed -->
        <mu1>100</mu1>
        <mu2>100</mu2>
        <kp>1000000.0</kp>
        <kd>1000.0</kd>
        <static>false</static>
    </gazebo>

    <!-- Gazebo specific properties for right_back_wheel -->
    <gazebo reference="right_back_wheel">
        <material>Gazebo/White</material> <!-- Adjust material as needed -->
        <mu1>100</mu1>
        <mu2>100</mu2>
        <kp>1000000.0</kp>
        <kd>1000.0</kd>
        <static>false</static>
    </gazebo>

    <gazebo reference="left_front_wheel">
        <material>Gazebo/White</material> <!-- Adjust material as needed -->
        <mu1>100</mu1>
        <mu2>100</mu2>
        <kp>1000000.0</kp>
        <kd>1000.0</kd>
        <static>false</static>
    </gazebo>

    <!-- Gazebo specific properties for right_front_wheel -->
    <gazebo reference="right_front_wheel">
        <material>Gazebo/White</material> <!-- Adjust material as needed -->
        <mu1>100</mu1>
        <mu2>100</mu2>
        <kp>1000000.0</kp>
        <kd>1000.0</kd>
        <static>false</static>
    </gazebo>

    <gazebo>
        <plugin name="diff_drive_controller" filename="libgazebo_ros_diff_drive.so">
          <updateRate>100.0</updateRate>
          <robotNamespace>/</robotNamespace>
          <num_wheel_pairs>2</num_wheel_pairs>
          <left_joint>base_left_front_joint</left_joint>
          <left_joint>base_left_wheel_joint</left_joint>
          <right_joint>base_right_front_joint</right_joint>
          <right_joint>base_right_back_joint</right_joint>
          <wheel_separation>0.6</wheel_separation>
          <wheel_separation>0.6</wheel_separation>
          <wheel_diameter>0.2</wheel_diameter>
          <wheel_diameter>0.2</wheel_diameter>
          <robotBaseFrame>base_link</robotBaseFrame>
          <torque>20</torque>
          <topicName>cmd_vel</topicName>
          <broadcastTF>false</broadcastTF>
        </plugin>
    </gazebo>

</robot>
