<?xml version="1.0"?>
<robot name="my_robot">

    <material name="grey">
        <color rgba="0.7 0.7 0.7 1" />
    </material>
    <material name="green">
        <color rgba="0 0.6 0 1" />
    </material>
    <material name="white">
        <color rgba="1 1 1 1" />
    </material>


    <link name="base_footprint" />

    <link name="base_link">
        <visual>
            <geometry>
                <box size="0.6 0.4 0.2" />
            </geometry>
            <origin xyz="0 0 0.1" rpy="0 0 0" />
            <material name="green" />
        </visual>
    </link>

    <link name="lidar">
        <visual>
            <geometry>
                <cylinder radius="0.1" length= "0.05" />
            </geometry>
            <origin xyz="0 0 0" rpy="0 0 0" />
            <material name="white" />
        </visual>
    </link>

    <link name="left_back_wheel">
        <visual>
            <geometry>
                <cylinder radius="0.1" length= "0.05" />
            </geometry>
            <origin xyz="0 0 0" rpy="1.57 0 0" />
            <material name="white" />
        </visual>
    </link>

    <link name="right_back_wheel">
        <visual>
            <geometry>
                <cylinder radius="0.1" length= "0.05" />
            </geometry>
            <origin xyz="0 0 0" rpy="1.57 0 0" />
            <material name="white" />
        </visual>
    </link>
    
    <link name="left_front_wheel">
        <visual>
            <geometry>
                <cylinder radius="0.1" length= "0.05" />
            </geometry>
            <origin xyz="0 0 0" rpy="1.57 0 0" />
            <material name="white" />
        </visual>
    </link>

    <link name="right_front_wheel">
        <visual>
            <geometry>
                <cylinder radius="0.1" length= "0.05" />
            </geometry>
            <origin xyz="0 0 0" rpy="1.57 0 0" />
            <material name="white" />
        </visual>
    </link>
    
    <joint name="base_joint" type="fixed">
        <parent link="base_footprint" />
        <child link="base_link" />
        <origin xyz="0 0 0.1" rpy="0 0 0" />
    </joint>

    <joint name="base_lidar_joint" type="fixed">
        <parent link="base_link" />
        <child link="lidar" />
        <origin xyz="0 0 0.225" rpy="0 0 0" />
    </joint>

    <joint name="base_left_wheel_joint" type="continuous">
        <parent link="base_link" />
        <child link="left_back_wheel" />
        <origin xyz="-0.15 0.225 0" rpy="0 0 0" />
        <axis xyz ="0 1 0" />
    </joint>

    <joint name="base_left_front_joint" type="continuous">
        <parent link="base_link" />
        <child link="left_front_wheel" />
        <origin xyz="0.15 0.225 0" rpy="0 0 0" />
        <axis xyz ="0 1 0" />
    </joint>

    <joint name="base_right_front_joint" type="continuous">
        <parent link="base_link" />
        <child link="right_front_wheel" />
        <origin xyz="0.15 -0.225 0" rpy="0 0 0" />
        <axis xyz ="0 1 0" />
    </joint>

    <joint name="base_right_back_joint" type="continuous">
        <parent link="base_link" />
        <child link="right_back_wheel" />
        <origin xyz="-0.15 -0.225 0" rpy="0 0 0" />
        <axis xyz ="0 1 0" />
    </joint>

</robot>